[2025-03-17T20:06:24.103+0000] {local_task_job_runner.py:120} INFO - ::group::Pre task execution logs
[2025-03-17T20:06:24.156+0000] {taskinstance.py:2076} INFO - Dependencies all met for dep_context=non-requeueable deps ti=<TaskInstance: my_dag._choose_best_model scheduled__2025-03-16T00:00:00+00:00 [queued]>
[2025-03-17T20:06:24.179+0000] {taskinstance.py:2076} INFO - Dependencies all met for dep_context=requeueable deps ti=<TaskInstance: my_dag._choose_best_model scheduled__2025-03-16T00:00:00+00:00 [queued]>
[2025-03-17T20:06:24.182+0000] {taskinstance.py:2306} INFO - Starting attempt 1 of 1
[2025-03-17T20:06:24.240+0000] {taskinstance.py:2330} INFO - Executing <Task(BranchPythonOperator): _choose_best_model> on 2025-03-16 00:00:00+00:00
[2025-03-17T20:06:24.262+0000] {warnings.py:110} WARNING - /home/***/.local/lib/python3.12/site-packages/***/task/task_runner/standard_task_runner.py:61: DeprecationWarning: This process (pid=248) is multi-threaded, use of fork() may lead to deadlocks in the child.
  pid = os.fork()

[2025-03-17T20:06:24.266+0000] {standard_task_runner.py:90} INFO - Running: ['***', 'tasks', 'run', 'my_dag', '_choose_best_model', 'scheduled__2025-03-16T00:00:00+00:00', '--job-id', '16', '--raw', '--subdir', 'DAGS_FOLDER/my_dag.py', '--cfg-path', '/tmp/tmppbm2masc']
[2025-03-17T20:06:24.275+0000] {standard_task_runner.py:63} INFO - Started process 251 to run task
[2025-03-17T20:06:24.281+0000] {standard_task_runner.py:91} INFO - Job 16: Subtask _choose_best_model
[2025-03-17T20:06:24.451+0000] {task_command.py:426} INFO - Running <TaskInstance: my_dag._choose_best_model scheduled__2025-03-16T00:00:00+00:00 [running]> on host 7ed0592ccd5e
[2025-03-17T20:06:24.574+0000] {taskinstance.py:2648} INFO - Exporting env vars: AIRFLOW_CTX_DAG_OWNER='***' AIRFLOW_CTX_DAG_ID='my_dag' AIRFLOW_CTX_TASK_ID='_choose_best_model' AIRFLOW_CTX_EXECUTION_DATE='2025-03-16T00:00:00+00:00' AIRFLOW_CTX_TRY_NUMBER='1' AIRFLOW_CTX_DAG_RUN_ID='scheduled__2025-03-16T00:00:00+00:00'
[2025-03-17T20:06:24.576+0000] {taskinstance.py:430} INFO - ::endgroup::
[2025-03-17T20:06:24.588+0000] {baseoperator.py:399} WARNING - BranchPythonOperator.execute cannot be called outside TaskInstance!
[2025-03-17T20:06:24.590+0000] {taskinstance.py:441} INFO - ::group::Post task execution logs
[2025-03-17T20:06:24.591+0000] {taskinstance.py:2905} ERROR - Task failed with exception
Traceback (most recent call last):
  File "/home/airflow/.local/lib/python3.12/site-packages/airflow/models/taskinstance.py", line 465, in _execute_task
    result = _execute_callable(context=context, **execute_callable_kwargs)
             ^^^^^^^^^^^^^^^^^^^^^^^^^^^^^^^^^^^^^^^^^^^^^^^^^^^^^^^^^^^^^
  File "/home/airflow/.local/lib/python3.12/site-packages/airflow/models/taskinstance.py", line 432, in _execute_callable
    return execute_callable(context=context, **execute_callable_kwargs)
           ^^^^^^^^^^^^^^^^^^^^^^^^^^^^^^^^^^^^^^^^^^^^^^^^^^^^^^^^^^^^
  File "/home/airflow/.local/lib/python3.12/site-packages/airflow/models/baseoperator.py", line 400, in wrapper
    return func(self, *args, **kwargs)
           ^^^^^^^^^^^^^^^^^^^^^^^^^^^
  File "/home/airflow/.local/lib/python3.12/site-packages/airflow/operators/python.py", line 269, in execute
    return self.do_branch(context, super().execute(context))
                                   ^^^^^^^^^^^^^^^^^^^^^^^^
  File "/home/airflow/.local/lib/python3.12/site-packages/airflow/models/baseoperator.py", line 400, in wrapper
    return func(self, *args, **kwargs)
           ^^^^^^^^^^^^^^^^^^^^^^^^^^^
  File "/home/airflow/.local/lib/python3.12/site-packages/airflow/operators/python.py", line 235, in execute
    return_value = self.execute_callable()
                   ^^^^^^^^^^^^^^^^^^^^^^^
  File "/home/airflow/.local/lib/python3.12/site-packages/airflow/operators/python.py", line 252, in execute_callable
    return self.python_callable(*self.op_args, **self.op_kwargs)
           ^^^^^^^^^^^^^^^^^^^^^^^^^^^^^^^^^^^^^^^^^^^^^^^^^^^^^
  File "/opt/airflow/dags/my_dag.py", line 17, in _choose_best_model
    best_accuracy = max()
                    ^^^^^
TypeError: max expected at least 1 argument, got 0
[2025-03-17T20:06:24.608+0000] {taskinstance.py:1206} INFO - Marking task as FAILED. dag_id=my_dag, task_id=_choose_best_model, run_id=scheduled__2025-03-16T00:00:00+00:00, execution_date=20250316T000000, start_date=20250317T200624, end_date=20250317T200624
[2025-03-17T20:06:24.624+0000] {standard_task_runner.py:110} ERROR - Failed to execute job 16 for task _choose_best_model (max expected at least 1 argument, got 0; 251)
[2025-03-17T20:06:24.662+0000] {local_task_job_runner.py:240} INFO - Task exited with return code 1
[2025-03-17T20:06:24.735+0000] {taskinstance.py:3498} INFO - 0 downstream tasks scheduled from follow-on schedule check
[2025-03-17T20:06:24.746+0000] {local_task_job_runner.py:222} INFO - ::endgroup::
