[2025-03-17T20:06:24.086+0000] {local_task_job_runner.py:120} INFO - ::group::Pre task execution logs
[2025-03-17T20:06:24.140+0000] {taskinstance.py:2076} INFO - Dependencies all met for dep_context=non-requeueable deps ti=<TaskInstance: my_dag._choose_best_model manual__2025-03-17T20:06:21.137909+00:00 [queued]>
[2025-03-17T20:06:24.160+0000] {taskinstance.py:2076} INFO - Dependencies all met for dep_context=requeueable deps ti=<TaskInstance: my_dag._choose_best_model manual__2025-03-17T20:06:21.137909+00:00 [queued]>
[2025-03-17T20:06:24.166+0000] {taskinstance.py:2306} INFO - Starting attempt 1 of 1
[2025-03-17T20:06:24.225+0000] {taskinstance.py:2330} INFO - Executing <Task(BranchPythonOperator): _choose_best_model> on 2025-03-17 20:06:21.137909+00:00
[2025-03-17T20:06:24.243+0000] {warnings.py:110} WARNING - /home/***/.local/lib/python3.12/site-packages/***/task/task_runner/standard_task_runner.py:61: DeprecationWarning: This process (pid=249) is multi-threaded, use of fork() may lead to deadlocks in the child.
  pid = os.fork()

[2025-03-17T20:06:24.250+0000] {standard_task_runner.py:90} INFO - Running: ['***', 'tasks', 'run', 'my_dag', '_choose_best_model', 'manual__2025-03-17T20:06:21.137909+00:00', '--job-id', '15', '--raw', '--subdir', 'DAGS_FOLDER/my_dag.py', '--cfg-path', '/tmp/tmp2urwerth']
[2025-03-17T20:06:24.253+0000] {standard_task_runner.py:63} INFO - Started process 250 to run task
[2025-03-17T20:06:24.255+0000] {standard_task_runner.py:91} INFO - Job 15: Subtask _choose_best_model
[2025-03-17T20:06:24.428+0000] {task_command.py:426} INFO - Running <TaskInstance: my_dag._choose_best_model manual__2025-03-17T20:06:21.137909+00:00 [running]> on host 7ed0592ccd5e
[2025-03-17T20:06:24.568+0000] {taskinstance.py:2648} INFO - Exporting env vars: AIRFLOW_CTX_DAG_OWNER='***' AIRFLOW_CTX_DAG_ID='my_dag' AIRFLOW_CTX_TASK_ID='_choose_best_model' AIRFLOW_CTX_EXECUTION_DATE='2025-03-17T20:06:21.137909+00:00' AIRFLOW_CTX_TRY_NUMBER='1' AIRFLOW_CTX_DAG_RUN_ID='manual__2025-03-17T20:06:21.137909+00:00'
[2025-03-17T20:06:24.570+0000] {taskinstance.py:430} INFO - ::endgroup::
[2025-03-17T20:06:24.583+0000] {baseoperator.py:399} WARNING - BranchPythonOperator.execute cannot be called outside TaskInstance!
[2025-03-17T20:06:24.586+0000] {taskinstance.py:441} INFO - ::group::Post task execution logs
[2025-03-17T20:06:24.587+0000] {taskinstance.py:2905} ERROR - Task failed with exception
Traceback (most recent call last):
  File "/home/airflow/.local/lib/python3.12/site-packages/airflow/models/taskinstance.py", line 465, in _execute_task
    result = _execute_callable(context=context, **execute_callable_kwargs)
             ^^^^^^^^^^^^^^^^^^^^^^^^^^^^^^^^^^^^^^^^^^^^^^^^^^^^^^^^^^^^^
  File "/home/airflow/.local/lib/python3.12/site-packages/airflow/models/taskinstance.py", line 432, in _execute_callable
    return execute_callable(context=context, **execute_callable_kwargs)
           ^^^^^^^^^^^^^^^^^^^^^^^^^^^^^^^^^^^^^^^^^^^^^^^^^^^^^^^^^^^^
  File "/home/airflow/.local/lib/python3.12/site-packages/airflow/models/baseoperator.py", line 400, in wrapper
    return func(self, *args, **kwargs)
           ^^^^^^^^^^^^^^^^^^^^^^^^^^^
  File "/home/airflow/.local/lib/python3.12/site-packages/airflow/operators/python.py", line 269, in execute
    return self.do_branch(context, super().execute(context))
                                   ^^^^^^^^^^^^^^^^^^^^^^^^
  File "/home/airflow/.local/lib/python3.12/site-packages/airflow/models/baseoperator.py", line 400, in wrapper
    return func(self, *args, **kwargs)
           ^^^^^^^^^^^^^^^^^^^^^^^^^^^
  File "/home/airflow/.local/lib/python3.12/site-packages/airflow/operators/python.py", line 235, in execute
    return_value = self.execute_callable()
                   ^^^^^^^^^^^^^^^^^^^^^^^
  File "/home/airflow/.local/lib/python3.12/site-packages/airflow/operators/python.py", line 252, in execute_callable
    return self.python_callable(*self.op_args, **self.op_kwargs)
           ^^^^^^^^^^^^^^^^^^^^^^^^^^^^^^^^^^^^^^^^^^^^^^^^^^^^^
  File "/opt/airflow/dags/my_dag.py", line 17, in _choose_best_model
    best_accuracy = max()
                    ^^^^^
TypeError: max expected at least 1 argument, got 0
[2025-03-17T20:06:24.607+0000] {taskinstance.py:1206} INFO - Marking task as FAILED. dag_id=my_dag, task_id=_choose_best_model, run_id=manual__2025-03-17T20:06:21.137909+00:00, execution_date=20250317T200621, start_date=20250317T200624, end_date=20250317T200624
[2025-03-17T20:06:24.627+0000] {standard_task_runner.py:110} ERROR - Failed to execute job 15 for task _choose_best_model (max expected at least 1 argument, got 0; 250)
[2025-03-17T20:06:24.678+0000] {local_task_job_runner.py:240} INFO - Task exited with return code 1
[2025-03-17T20:06:24.741+0000] {taskinstance.py:3498} INFO - 0 downstream tasks scheduled from follow-on schedule check
[2025-03-17T20:06:24.750+0000] {local_task_job_runner.py:222} INFO - ::endgroup::
